Workbook

Sheet 📥 Data Source
A1: 🏧 RETRAITS NON SERVIS — 2025 | DATA SOURCE
A2: Extraction : 02/06/2026 | ⚠️ Supprime les lignes exemple puis colle tes données en A5 avec CTRL+V
A4: DATE_OPERATION (DDMMYYYY) | B4: NUM_AUTOMATE | C4: LIB_SIT_ IMPLEMENTATION | D4: CODE_SITE_ IMPLEMENTATION | E4: TYPE_PORTEUR | F4: NB_RETRAIT_ NON_ABOUTIS | G4: MONTANT | H4: MOTIF
A5: 01012025 | B5: 740121 | C5: ANNEMASSE PRINCIPAL | D5: 74012 | E5: Porteur | F5: 1 | G5: 250
A6: 01012025 | B6: 751771 | C6: PARIS PHILIPPE GIRARD | D6: 75177 | E6: Non porteur | F6: 1 | G6: 100
A7: 01012025 | B7: 756292 | C7: PARIS CHATEAU ROUGE | D7: 75629 | E7: Porteur | F7: 2 | G7: 460
A8: 01012025 | B8: 756931 | C8: PARIS LOUIS BLANC | D8: 75693 | E8: Non porteur | F8: 1 | G8: 10
A9: 01012025 | B9: 913261 | C9: JUVISY SUR ORGE | D9: 91326 | E9: Porteur | F9: 1 | G9: 600
A11: ⚠️ Supprime les lignes 5 à 9, colle tes données en A5 avec CTRL+V (collage spécial → Valeurs)

Sheet 📊 Par Automate
A1: 📊 ANALYSE PAR AUTOMATE
A2: Extraction : 02/06/2026 | Résultats calculés automatiquement depuis Data Source
A4: ⚡ INDICATEURS CLÉS GLOBAUX
A5: Total Lignes | B5: Nb Retraits Non Aboutis | C5: Montant Total (€) | D5: Retraits Porteurs | E5: Montant Porteurs (€) | F5: Montant Non Porteurs (€)
A6: =COUNTA('📥 Data Source'!B5:B38201) -> 0 | B6: =SUM('📥 Data Source'!F5:F38201) -> 0 | C6: =SUM('📥 Data Source'!G5:G38201) -> 0 | D6: =SUMIF('📥 Data Source'!E5:E38201,"Porteur",'📥 Data Source'!F5:F38201) -> 0 | E6: =SUMIF('📥 Data Source'!E5:E38201,"Porteur",'📥 Data Source'!G5:G38201) -> 0 | F6: =SUMIF('📥 Data Source'!E5:E38201,"Non porteur",'📥 Data Source'!G5:G38201) -> 0
A8: 📋 RÉCAPITULATIF PAR NUM_AUTOMATE — dynamique
A9: NUM_AUTOMATE | B9: LIB_SIT_IMPLEMENTATION | C9: NB RETRAITS NON ABOUTIS | D9: MONTANT TOTAL (€) | E9: NB OPS PORTEURS | F9: NB OPS NON PORTEURS
A10: {=IFERROR(INDEX('📥 Data Source'!$B$5:$B$38201,MATCH(0,COUNTIF($A$9:A9,'📥 Data Source'!$B$5:$B$38201)+IF('📥 Data Source'!$B$5:$B$38201="",1,0),0)),"")} -> 0 | B10: =IFERROR(IF(A10="","",INDEX('📥 Data Source'!$C$5:$C$38201,MATCH(A10,'📥 Data Source'!$B$5:$B$38201,0))),"") -> 0 | C10: =IF(A10="","",SUMIF('📥 Data Source'!$B$5:$B$38201,A10,'📥 Data Source'!$F$5:$F$38201)) -> 0 | D10: =IF(A10="","",SUMIF('📥 Data Source'!$B$5:$B$38201,A10,'📥 Data Source'!$G$5:$G$38201)) -> 0 | E10: =IF(A10="","",COUNTIFS('📥 Data Source'!$B$5:$B$38201,A10,'📥 Data Source'!$E$5:$E$38201,"Porteur")) -> 0 | F10: =IF(A10="","",COUNTIFS('📥 Data Source'!$B$5:$B$38201,A10,'📥 Data Source'!$E$5:$E$38201,"Non porteur")) -> 0
A11: {=IFERROR(INDEX('📥 Data Source'!$B$5:$B$38201,MATCH(0,COUNTIF($A$9:A10,'📥 Data Source'!$B$5:$B$38201)+IF('📥 Data Source'!$B$5:$B$38201="",1,0),0)),"")} -> 0 | B11: =IFERROR(IF(A11="","",INDEX('📥 Data Source'!$C$5:$C$38201,MATCH(A11,'📥 Data Source'!$B$5:$B$38201,0))),"") -> 0 | C11: =IF(A11="","",SUMIF('📥 Data Source'!$B$5:$B$38201,A11,'📥 Data Source'!$F$5:$F$38201)) -> 0 | D11: =IF(A11="","",SUMIF('📥 Data Source'!$B$5:$B$38201,A11,'📥 Data Source'!$G$5:$G$38201)) -> 0 | E11: =IF(A11="","",COUNTIFS('📥 Data Source'!$B$5:$B$38201,A11,'📥 Data Source'!$E$5:$E$38201,"Porteur")) -> 0 | F11: =IF(A11="","",COUNTIFS('📥 Data Source'!$B$5:$B$38201,A11,'📥 Data Source'!$E$5:$E$38201,"Non porteur")) -> 0
A12: {=IFERROR(INDEX('📥 Data Source'!$B$5:$B$38201,MATCH(0,COUNTIF($A$9:A11,'📥 Data Source'!$B$5:$B$38201)+IF('📥 Data Source'!$B$5:$B$38201="",1,0),0)),"")} -> 0 | B12: =IFERROR(IF(A12="","",INDEX('📥 Data Source'!$C$5:$C$38201,MATCH(A12,'📥 Data Source'!$B$5:$B$38201,0))),"") -> 0 | C12: =IF(A12="","",SUMIF('📥 Data Source'!$B$5:$B$38201,A12,'📥 Data Source'!$F$5:$F$38201)) -> 0 | D12: =IF(A12="","",SUMIF('📥 Data Source'!$B$5:$B$38201,A12,'📥 Data Source'!$G$5:$G$38201)) -> 0 | E12: =IF(A12="","",COUNTIFS('📥 Data Source'!$B$5:$B$38201,A12,'📥 Data Source'!$E$5:$E$38201,"Porteur")) -> 0 | F12: =IF(A12="","",COUNTIFS('📥 Data Source'!$B$5:$B$38201,A12,'📥 Data Source'!$E$5:$E$38201,"Non porteur")) -> 0
A13: {=IFERROR(INDEX('📥 Data Source'!$B$5:$B$38201,MATCH(0,COUNTIF($A$9:A12,'📥 Data Source'!$B$5:$B$38201)+IF('📥 Data Source'!$B$5:$B$38201="",1,0),0)),"")} -> 0 | B13: =IFERROR(IF(A13="","",INDEX('📥 Data Source'!$C$5:$C$38201,MATCH(A13,'📥 Data Source'!$B$5:$B$38201,0))),"") -> 0 | C13: =IF(A13="","",SUMIF('📥 Data Source'!$B$5:$B$38201,A13,'📥 Data Source'!$F$5:$F$38201)) -> 0 | D13: =IF(A13="","",SUMIF('📥 Data Source'!$B$5:$B$38201,A13,'📥 Data Source'!$G$5:$G$38201)) -> 0 | E13: =IF(A13="","",COUNTIFS('📥 Data Source'!$B$5:$B$38201,A13,'📥 Data Source'!$E$5:$E$38201,"Porteur")) -> 0 | F13: =IF(A13="","",COUNTIFS('📥 Data Source'!$B$5:$B$38201,A13,'📥 Data Source'!$E$5:$E$38201,"Non porteur")) -> 0
A14: {=IFERROR(INDEX('📥 Data Source'!$B$5:$B$38201,MATCH(0,COUNTIF($A$9:A13,'📥 Data Source'!$B$5:$B$38201)+IF('📥 Data Source'!$B$5:$B$38201="",1,0),0)),"")} -> 0 | B14: =IFERROR(IF(A14="","",INDEX('📥 Data Source'!$C$5:$C$38201,MATCH(A14,'📥 Data Source'!$B$5:$B$38201,0))),"") -> 0 | C14: =IF(A14="","",SUMIF('📥 Data Source'!$B$5:$B$38201,A14,'📥 Data Source'!$F$5:$F$38201)) -> 0 | D14: =IF(A14="","",SUMIF('📥 Data Source'!$B$5:$B$38201,A14,'📥 Data Source'!$G$5:$G$38201)) -> 0 | E14: =IF(A14="","",COUNTIFS('📥 Data Source'!$B$5:$B$38201,A14,'📥 Data Source'!$E$5:$E$38201,"Porteur")) -> 0 | F14: =IF(A14="","",COUNTIFS('📥 Data Source'!$B$5:$B$38201,A14,'📥 Data Source'!$E$5:$E$38201,"Non porteur")) -> 0
A15: {=IFERROR(INDEX('📥 Data Source'!$B$5:$B$38201,MATCH(0,COUNTIF($A$9:A14,'📥 Data Source'!$B$5:$B$38201)+IF('📥 Data Source'!$B$5:$B$38201="",1,0),0)),"")} -> 0 | B15: =IFERROR(IF(A15="","",INDEX('📥 Data Source'!$C$5:$C$38201,MATCH(A15,'📥 Data Source'!$B$5:$B$38201,0))),"") -> 0 | C15: =IF(A15="","",SUMIF('📥 Data Source'!$B$5:$B$38201,A15,'📥 Data Source'!$F$5:$F$38201)) -> 0 | D15: =IF(A15="","",SUMIF('📥 Data Source'!$B$5:$B$38201,A15,'📥 Data Source'!$G$5:$G$38201)) -> 0 | E15: =IF(A15="","",COUNTIFS('📥 Data Source'!$B$5:$B$38201,A15,'📥 Data Source'!$E$5:$E$38201,"Porteur")) -> 0 | F15: =IF(A15="","",COUNTIFS('📥 Data Source'!$B$5:$B$38201,A15,'📥 Data Source'!$E$5:$E$38201,"Non porteur")) -> 0
A16: {=IFERROR(INDEX('📥 Data Source'!$B$5:$B$38201,MATCH(0,COUNTIF($A$9:A15,'📥 Data Source'!$B$5:$B$38201)+IF('📥 Data Source'!$B$5:$B$38201="",1,0),0)),"")} -> 0 | B16: =IFERROR(IF(A16="","",INDEX('📥 Data Source'!$C$5:$C$38201,MATCH(A16,'📥 Data Source'!$B$5:$B$38201,0))),"") -> 0 | C16: =IF(A16="","",SUMIF('📥 Data Source'!$B$5:$B$38201,A16,'📥 Data Source'!$F$5:$F$38201)) -> 0 | D16: =IF(A16="","",SUMIF('📥 Data Source'!$B$5:$B$38201,A16,'📥 Data Source'!$G$5:$G$38201)) -> 0 | E16: =IF(A16="","",COUNTIFS('📥 Data Source'!$B$5:$B$38201,A16,'📥 Data Source'!$E$5:$E$38201,"Porteur")) -> 0 | F16: =IF(A16="","",COUNTIFS('📥 Data Source'!$B$5:$B$38201,A16,'📥 Data Source'!$E$5:$E$38201,"Non porteur")) -> 0
A17: {=IFERROR(INDEX('📥 Data Source'!$B$5:$B$38201,MATCH(0,COUNTIF($A$9:A16,'📥 Data Source'!$B$5:$B$38201)+IF('📥 Data Source'!$B$5:$B$38201="",1,0),0)),"")} -> 0 | B17: =IFERROR(IF(A17="","",INDEX('📥 Data Source'!$C$5:$C$38201,MATCH(A17,'📥 Data Source'!$B$5:$B$38201,0))),"") -> 0 | C17: =IF(A17="","",SUMIF('📥 Data Source'!$B$5:$B$38201,A17,'📥 Data Source'!$F$5:$F$38201)) -> 0 | D17: =IF(A17="","",SUMIF('📥 Data Source'!$B$5:$B$38201,A17,'📥 Data Source'!$G$5:$G$38201)) -> 0 | E17: =IF(A17="","",COUNTIFS('📥 Data Source'!$B$5:$B$38201,A17,'📥 Data Source'!$E$5:$E$38201,"Porteur")) -> 0 | F17: =IF(A17="","",COUNTIFS('📥 Data Source'!$B$5:$B$38201,A17,'📥 Data Source'!$E$5:$E$38201,"Non porteur")) -> 0
A18: {=IFERROR(INDEX('📥 Data Source'!$B$5:$B$38201,MATCH(0,COUNTIF($A$9:A17,'📥 Data Source'!$B$5:$B$38201)+IF('📥 Data Source'!$B$5:$B$38201="",1,0),0)),"")} -> 0 | B18: =IFERROR(IF(A18="","",INDEX('📥 Data Source'!$C$5:$C$38201,MATCH(A18,'📥 Data Source'!$B$5:$B$38201,0))),"") -> 0 | C18: =IF(A18="","",SUMIF('📥 Data Source'!$B$5:$B$38201,A18,'📥 Data Source'!$F$5:$F$38201)) -> 0 | D18: =IF(A18="","",SUMIF('📥 Data Source'!$B$5:$B$38201,A18,'📥 Data Source'!$G$5:$G$38201)) -> 0 | E18: =IF(A18="","",COUNTIFS('📥 Data Source'!$B$5:$B$38201,A18,'📥 Data Source'!$E$5:$E$38201,"Porteur")) -> 0 | F18: =IF(A18="","",COUNTIFS('📥 Data Source'!$B$5:$B$38201,A18,'📥 Data Source'!$E$5:$E$38201,"Non porteur")) -> 0
A19: {=IFERROR(INDEX('📥 Data Source'!$B$5:$B$38201,MATCH(0,COUNTIF($A$9:A18,'📥 Data Source'!$B$5:$B$38201)+IF('📥 Data Source'!$B$5:$B$38201="",1,0),0)),"")} -> 0 | B19: =IFERROR(IF(A19="","",INDEX('📥 Data Source'!$C$5:$C$38201,MATCH(A19,'📥 Data Source'!$B$5:$B$38201,0))),"") -> 0 | C19: =IF(A19="","",SUMIF('📥 Data Source'!$B$5:$B$38201,A19,'📥 Data Source'!$F$5:$F$38201)) -> 0 | D19: =IF(A19="","",SUMIF('📥 Data Source'!$B$5:$B$38201,A19,'📥 Data Source'!$G$5:$G$38201)) -> 0 | E19: =IF(A19="","",COUNTIFS('📥 Data Source'!$B$5:$B$38201,A19,'📥 Data Source'!$E$5:$E$38201,"Porteur")) -> 0 | F19: =IF(A19="","",COUNTIFS('📥 Data Source'!$B$5:$B$38201,A19,'📥 Data Source'!$E$5:$E$38201,"Non porteur")) -> 0
A20: {=IFERROR(INDEX('📥 Data Source'!$B$5:$B$38201,MATCH(0,COUNTIF($A$9:A19,'📥 Data Source'!$B$5:$B$38201)+IF('📥 Data Source'!$B$5:$B$38201="",1,0),0)),"")} -> 0 | B20: =IFERROR(IF(A20="","",INDEX('📥 Data Source'!$C$5:$C$38201,MATCH(A20,'📥 Data Source'!$B$5:$B$38201,0))),"") -> 0 | C20: =IF(A20="","",SUMIF('📥 Data Source'!$B$5:$B$38201,A20,'📥 Data Source'!$F$5:$F$38201)) -> 0 | D20: =IF(A20="","",SUMIF('📥 Data Source'!$B$5:$B$38201,A20,'📥 Data Source'!$G$5:$G$38201)) -> 0 | E20: =IF(A20="","",COUNTIFS('📥 Data Source'!$B$5:$B$38201,A20,'📥 Data Source'!$E$5:$E$38201,"Porteur")) -> 0 | F20: =IF(A20="","",COUNTIFS('📥 Data Source'!$B$5:$B$38201,A20,'📥 Data Source'!$E$5:$E$38201,"Non porteur")) -> 0
A21: {=IFERROR(INDEX('📥 Data Source'!$B$5:$B$38201,MATCH(0,COUNTIF($A$9:A20,'📥 Data Source'!$B$5:$B$38201)+IF('📥 Data Source'!$B$5:$B$38201="",1,0),0)),"")} -> 0 | B21: =IFERROR(IF(A21="","",INDEX('📥 Data Source'!$C$5:$C$38201,MATCH(A21,'📥 Data Source'!$B$5:$B$38201,0))),"") -> 0 | C21: =IF(A21="","",SUMIF('📥 Data Source'!$B$5:$B$38201,A21,'📥 Data Source'!$F$5:$F$38201)) -> 0 | D21: =IF(A21="","",SUMIF('📥 Data Source'!$B$5:$B$38201,A21,'📥 Data Source'!$G$5:$G$38201)) -> 0 | E21: =IF(A21="","",COUNTIFS('📥 Data Source'!$B$5:$B$38201,A21,'📥 Data Source'!$E$5:$E$38201,"Porteur")) -> 0 | F21: =IF(A21="","",COUNTIFS('📥 Data Source'!$B$5:$B$38201,A21,'📥 Data Source'!$E$5:$E$38201,"Non porteur")) -> 0
... A59: {=IFERROR(INDEX('📥 Data Source'!$B$5:$B$38201,MATCH(0,COUNTIF($A$9:A58,'📥 Data Source'!$B$5:$B$38201)+IF('📥 Data Source'!$B$5:$B$38201="",1,0),0)),"")} -> 0 | B59: =IFERROR(IF(A59="","",INDEX('📥 Data Source'!$C$5:$C$38201,MATCH(A59,'📥 Data Source'!$B$5:$B$38201,0))),"") -> 0 | C59: =IF(A59="","",SUMIF('📥 Data Source'!$B$5:$B$38201,A59,'📥 Data Source'!$F$5:$F$38201)) -> 0 | D59: =IF(A59="","",SUMIF('📥 Data Source'!$B$5:$B$38201,A59,'📥 Data Source'!$G$5:$G$38201)) -> 0 | E59: =IF(A59="","",COUNTIFS('📥 Data Source'!$B$5:$B$38201,A59,'📥 Data Source'!$E$5:$E$38201,"Porteur")) -> 0 | F59: =IF(A59="","",COUNTIFS('📥 Data Source'!$B$5:$B$38201,A59,'📥 Data Source'!$E$5:$E$38201,"Non porteur")) -> 0
A60: TOTAL | C60: =SUM(C10:C59) -> 0 | D60: =SUM(D10:D59) -> 0 | E60: =SUM(E10:E59) -> 0 | F60: =SUM(F10:F59) -> 0

Sheet 🏢 Par Site
A1: 🏢 ANALYSE PAR SITE D'IMPLÉMENTATION
A2: Extraction : 02/06/2026 | Résultats calculés automatiquement depuis Data Source
A4: 📋 RÉCAPITULATIF PAR CODE_SITE_IMPLEMENTATION — dynamique
A5: CODE SITE | B5: LIB SITE | C5: NB RETRAITS NON ABOUTIS | D5: MONTANT TOTAL (€) | E5: NB OPS PORTEURS | F5: NB OPS NON PORTEURS
A6: {=IFERROR(INDEX('📥 Data Source'!$D$5:$D$38201,MATCH(0,COUNTIF($A$4:A5,'📥 Data Source'!$D$5:$D$38201)+IF('📥 Data Source'!$D$5:$D$38201="",1,0),0)),"")} -> 0 | B6: =IFERROR(IF(A6="","",INDEX('📥 Data Source'!$C$5:$C$38201,MATCH(A6,'📥 Data Source'!$D$5:$D$38201,0))),"") -> 0 | C6: =IF(A6="","",SUMIF('📥 Data Source'!$D$5:$D$38201,A6,'📥 Data Source'!$F$5:$F$38201)) -> 0 | D6: =IF(A6="","",SUMIF('📥 Data Source'!$D$5:$D$38201,A6,'📥 Data Source'!$G$5:$G$38201)) -> 0 | E6: =IF(A6="","",COUNTIFS('📥 Data Source'!$D$5:$D$38201,A6,'📥 Data Source'!$E$5:$E$38201,"Porteur")) -> 0 | F6: =IF(A6="","",COUNTIFS('📥 Data Source'!$D$5:$D$38201,A6,'📥 Data Source'!$E$5:$E$38201,"Non porteur")) -> 0
A7: {=IFERROR(INDEX('📥 Data Source'!$D$5:$D$38201,MATCH(0,COUNTIF($A$4:A6,'📥 Data Source'!$D$5:$D$38201)+IF('📥 Data Source'!$D$5:$D$38201="",1,0),0)),"")} -> 0 | B7: =IFERROR(IF(A7="","",INDEX('📥 Data Source'!$C$5:$C$38201,MATCH(A7,'📥 Data Source'!$D$5:$D$38201,0))),"") -> 0 | C7: =IF(A7="","",SUMIF('📥 Data Source'!$D$5:$D$38201,A7,'📥 Data Source'!$F$5:$F$38201)) -> 0 | D7: =IF(A7="","",SUMIF('📥 Data Source'!$D$5:$D$38201,A7,'📥 Data Source'!$G$5:$G$38201)) -> 0 | E7: =IF(A7="","",COUNTIFS('📥 Data Source'!$D$5:$D$38201,A7,'📥 Data Source'!$E$5:$E$38201,"Porteur")) -> 0 | F7: =IF(A7="","",COUNTIFS('📥 Data Source'!$D$5:$D$38201,A7,'📥 Data Source'!$E$5:$E$38201,"Non porteur")) -> 0
A8: {=IFERROR(INDEX('📥 Data Source'!$D$5:$D$38201,MATCH(0,COUNTIF($A$4:A7,'📥 Data Source'!$D$5:$D$38201)+IF('📥 Data Source'!$D$5:$D$38201="",1,0),0)),"")} -> 0 | B8: =IFERROR(IF(A8="","",INDEX('📥 Data Source'!$C$5:$C$38201,MATCH(A8,'📥 Data Source'!$D$5:$D$38201,0))),"") -> 0 | C8: =IF(A8="","",SUMIF('📥 Data Source'!$D$5:$D$38201,A8,'📥 Data Source'!$F$5:$F$38201)) -> 0 | D8: =IF(A8="","",SUMIF('📥 Data Source'!$D$5:$D$38201,A8,'📥 Data Source'!$G$5:$G$38201)) -> 0 | E8: =IF(A8="","",COUNTIFS('📥 Data Source'!$D$5:$D$38201,A8,'📥 Data Source'!$E$5:$E$38201,"Porteur")) -> 0 | F8: =IF(A8="","",COUNTIFS('📥 Data Source'!$D$5:$D$38201,A8,'📥 Data Source'!$E$5:$E$38201,"Non porteur")) -> 0
A9: {=IFERROR(INDEX('📥 Data Source'!$D$5:$D$38201,MATCH(0,COUNTIF($A$4:A8,'📥 Data Source'!$D$5:$D$38201)+IF('📥 Data Source'!$D$5:$D$38201="",1,0),0)),"")} -> 0 | B9: =IFERROR(IF(A9="","",INDEX('📥 Data Source'!$C$5:$C$38201,MATCH(A9,'📥 Data Source'!$D$5:$D$38201,0))),"") -> 0 | C9: =IF(A9="","",SUMIF('📥 Data Source'!$D$5:$D$38201,A9,'📥 Data Source'!$F$5:$F$38201)) -> 0 | D9: =IF(A9="","",SUMIF('📥 Data Source'!$D$5:$D$38201,A9,'📥 Data Source'!$G$5:$G$38201)) -> 0 | E9: =IF(A9="","",COUNTIFS('📥 Data Source'!$D$5:$D$38201,A9,'📥 Data Source'!$E$5:$E$38201,"Porteur")) -> 0 | F9: =IF(A9="","",COUNTIFS('📥 Data Source'!$D$5:$D$38201,A9,'📥 Data Source'!$E$5:$E$38201,"Non porteur")) -> 0
A10: {=IFERROR(INDEX('📥 Data Source'!$D$5:$D$38201,MATCH(0,COUNTIF($A$4:A9,'📥 Data Source'!$D$5:$D$38201)+IF('📥 Data Source'!$D$5:$D$38201="",1,0),0)),"")} -> 0 | B10: =IFERROR(IF(A10="","",INDEX('📥 Data Source'!$C$5:$C$38201,MATCH(A10,'📥 Data Source'!$D$5:$D$38201,0))),"") -> 0 | C10: =IF(A10="","",SUMIF('📥 Data Source'!$D$5:$D$38201,A10,'📥 Data Source'!$F$5:$F$38201)) -> 0 | D10: =IF(A10="","",SUMIF('📥 Data Source'!$D$5:$D$38201,A10,'📥 Data Source'!$G$5:$G$38201)) -> 0 | E10: =IF(A10="","",COUNTIFS('📥 Data Source'!$D$5:$D$38201,A10,'📥 Data Source'!$E$5:$E$38201,"Porteur")) -> 0 | F10: =IF(A10="","",COUNTIFS('📥 Data Source'!$D$5:$D$38201,A10,'📥 Data Source'!$E$5:$E$38201,"Non porteur")) -> 0
A11: {=IFERROR(INDEX('📥 Data Source'!$D$5:$D$38201,MATCH(0,COUNTIF($A$4:A10,'📥 Data Source'!$D$5:$D$38201)+IF('📥 Data Source'!$D$5:$D$38201="",1,0),0)),"")} -> 0 | B11: =IFERROR(IF(A11="","",INDEX('📥 Data Source'!$C$5:$C$38201,MATCH(A11,'📥 Data Source'!$D$5:$D$38201,0))),"") -> 0 | C11: =IF(A11="","",SUMIF('📥 Data Source'!$D$5:$D$38201,A11,'📥 Data Source'!$F$5:$F$38201)) -> 0 | D11: =IF(A11="","",SUMIF('📥 Data Source'!$D$5:$D$38201,A11,'📥 Data Source'!$G$5:$G$38201)) -> 0 | E11: =IF(A11="","",COUNTIFS('📥 Data Source'!$D$5:$D$38201,A11,'📥 Data Source'!$E$5:$E$38201,"Porteur")) -> 0 | F11: =IF(A11="","",COUNTIFS('📥 Data Source'!$D$5:$D$38201,A11,'📥 Data Source'!$E$5:$E$38201,"Non porteur")) -> 0
A12: {=IFERROR(INDEX('📥 Data Source'!$D$5:$D$38201,MATCH(0,COUNTIF($A$4:A11,'📥 Data Source'!$D$5:$D$38201)+IF('📥 Data Source'!$D$5:$D$38201="",1,0),0)),"")} -> 0 | B12: =IFERROR(IF(A12="","",INDEX('📥 Data Source'!$C$5:$C$38201,MATCH(A12,'📥 Data Source'!$D$5:$D$38201,0))),"") -> 0 | C12: =IF(A12="","",SUMIF('📥 Data Source'!$D$5:$D$38201,A12,'📥 Data Source'!$F$5:$F$38201)) -> 0 | D12: =IF(A12="","",SUMIF('📥 Data Source'!$D$5:$D$38201,A12,'📥 Data Source'!$G$5:$G$38201)) -> 0 | E12: =IF(A12="","",COUNTIFS('📥 Data Source'!$D$5:$D$38201,A12,'📥 Data Source'!$E$5:$E$38201,"Porteur")) -> 0 | F12: =IF(A12="","",COUNTIFS('📥 Data Source'!$D$5:$D$38201,A12,'📥 Data Source'!$E$5:$E$38201,"Non porteur")) -> 0
A13: {=IFERROR(INDEX('📥 Data Source'!$D$5:$D$38201,MATCH(0,COUNTIF($A$4:A12,'📥 Data Source'!$D$5:$D$38201)+IF('📥 Data Source'!$D$5:$D$38201="",1,0),0)),"")} -> 0 | B13: =IFERROR(IF(A13="","",INDEX('📥 Data Source'!$C$5:$C$38201,MATCH(A13,'📥 Data Source'!$D$5:$D$38201,0))),"") -> 0 | C13: =IF(A13="","",SUMIF('📥 Data Source'!$D$5:$D$38201,A13,'📥 Data Source'!$F$5:$F$38201)) -> 0 | D13: =IF(A13="","",SUMIF('📥 Data Source'!$D$5:$D$38201,A13,'📥 Data Source'!$G$5:$G$38201)) -> 0 | E13: =IF(A13="","",COUNTIFS('📥 Data Source'!$D$5:$D$38201,A13,'📥 Data Source'!$E$5:$E$38201,"Porteur")) -> 0 | F13: =IF(A13="","",COUNTIFS('📥 Data Source'!$D$5:$D$38201,A13,'📥 Data Source'!$E$5:$E$38201,"Non porteur")) -> 0
A14: {=IFERROR(INDEX('📥 Data Source'!$D$5:$D$38201,MATCH(0,COUNTIF($A$4:A13,'📥 Data Source'!$D$5:$D$38201)+IF('📥 Data Source'!$D$5:$D$38201="",1,0),0)),"")} -> 0 | B14: =IFERROR(IF(A14="","",INDEX('📥 Data Source'!$C$5:$C$38201,MATCH(A14,'📥 Data Source'!$D$5:$D$38201,0))),"") -> 0 | C14: =IF(A14="","",SUMIF('📥 Data Source'!$D$5:$D$38201,A14,'📥 Data Source'!$F$5:$F$38201)) -> 0 | D14: =IF(A14="","",SUMIF('📥 Data Source'!$D$5:$D$38201,A14,'📥 Data Source'!$G$5:$G$38201)) -> 0 | E14: =IF(A14="","",COUNTIFS('📥 Data Source'!$D$5:$D$38201,A14,'📥 Data Source'!$E$5:$E$38201,"Porteur")) -> 0 | F14: =IF(A14="","",COUNTIFS('📥 Data Source'!$D$5:$D$38201,A14,'📥 Data Source'!$E$5:$E$38201,"Non porteur")) -> 0
A15: {=IFERROR(INDEX('📥 Data Source'!$D$5:$D$38201,MATCH(0,COUNTIF($A$4:A14,'📥 Data Source'!$D$5:$D$38201)+IF('📥 Data Source'!$D$5:$D$38201="",1,0),0)),"")} -> 0 | B15: =IFERROR(IF(A15="","",INDEX('📥 Data Source'!$C$5:$C$38201,MATCH(A15,'📥 Data Source'!$D$5:$D$38201,0))),"") -> 0 | C15: =IF(A15="","",SUMIF('📥 Data Source'!$D$5:$D$38201,A15,'📥 Data Source'!$F$5:$F$38201)) -> 0 | D15: =IF(A15="","",SUMIF('📥 Data Source'!$D$5:$D$38201,A15,'📥 Data Source'!$G$5:$G$38201)) -> 0 | E15: =IF(A15="","",COUNTIFS('📥 Data Source'!$D$5:$D$38201,A15,'📥 Data Source'!$E$5:$E$38201,"Porteur")) -> 0 | F15: =IF(A15="","",COUNTIFS('📥 Data Source'!$D$5:$D$38201,A15,'📥 Data Source'!$E$5:$E$38201,"Non porteur")) -> 0
A16: {=IFERROR(INDEX('📥 Data Source'!$D$5:$D$38201,MATCH(0,COUNTIF($A$4:A15,'📥 Data Source'!$D$5:$D$38201)+IF('📥 Data Source'!$D$5:$D$38201="",1,0),0)),"")} -> 0 | B16: =IFERROR(IF(A16="","",INDEX('📥 Data Source'!$C$5:$C$38201,MATCH(A16,'📥 Data Source'!$D$5:$D$38201,0))),"") -> 0 | C16: =IF(A16="","",SUMIF('📥 Data Source'!$D$5:$D$38201,A16,'📥 Data Source'!$F$5:$F$38201)) -> 0 | D16: =IF(A16="","",SUMIF('📥 Data Source'!$D$5:$D$38201,A16,'📥 Data Source'!$G$5:$G$38201)) -> 0 | E16: =IF(A16="","",COUNTIFS('📥 Data Source'!$D$5:$D$38201,A16,'📥 Data Source'!$E$5:$E$38201,"Porteur")) -> 0 | F16: =IF(A16="","",COUNTIFS('📥 Data Source'!$D$5:$D$38201,A16,'📥 Data Source'!$E$5:$E$38201,"Non porteur")) -> 0
A17: {=IFERROR(INDEX('📥 Data Source'!$D$5:$D$38201,MATCH(0,COUNTIF($A$4:A16,'📥 Data Source'!$D$5:$D$38201)+IF('📥 Data Source'!$D$5:$D$38201="",1,0),0)),"")} -> 0 | B17: =IFERROR(IF(A17="","",INDEX('📥 Data Source'!$C$5:$C$38201,MATCH(A17,'📥 Data Source'!$D$5:$D$38201,0))),"") -> 0 | C17: =IF(A17="","",SUMIF('📥 Data Source'!$D$5:$D$38201,A17,'📥 Data Source'!$F$5:$F$38201)) -> 0 | D17: =IF(A17="","",SUMIF('📥 Data Source'!$D$5:$D$38201,A17,'📥 Data Source'!$G$5:$G$38201)) -> 0 | E17: =IF(A17="","",COUNTIFS('📥 Data Source'!$D$5:$D$38201,A17,'📥 Data Source'!$E$5:$E$38201,"Porteur")) -> 0 | F17: =IF(A17="","",COUNTIFS('📥 Data Source'!$D$5:$D$38201,A17,'📥 Data Source'!$E$5:$E$38201,"Non porteur")) -> 0
... A55: {=IFERROR(INDEX('📥 Data Source'!$D$5:$D$38201,MATCH(0,COUNTIF($A$4:A54,'📥 Data Source'!$D$5:$D$38201)+IF('📥 Data Source'!$D$5:$D$38201="",1,0),0)),"")} -> 0 | B55: =IFERROR(IF(A55="","",INDEX('📥 Data Source'!$C$5:$C$38201,MATCH(A55,'📥 Data Source'!$D$5:$D$38201,0))),"") -> 0 | C55: =IF(A55="","",SUMIF('📥 Data Source'!$D$5:$D$38201,A55,'📥 Data Source'!$F$5:$F$38201)) -> 0 | D55: =IF(A55="","",SUMIF('📥 Data Source'!$D$5:$D$38201,A55,'📥 Data Source'!$G$5:$G$38201)) -> 0 | E55: =IF(A55="","",COUNTIFS('📥 Data Source'!$D$5:$D$38201,A55,'📥 Data Source'!$E$5:$E$38201,"Porteur")) -> 0 | F55: =IF(A55="","",COUNTIFS('📥 Data Source'!$D$5:$D$38201,A55,'📥 Data Source'!$E$5:$E$38201,"Non porteur")) -> 0
A56: TOTAL | C56: =SUM(C6:C55) -> 0 | D56: =SUM(D6:D55) -> 0 | E56: =SUM(E6:E55) -> 0 | F56: =SUM(F6:F55) -> 0

Sheet 👥 Porteur vs Non Porteur
A1: 👥 PORTEUR vs NON PORTEUR — COMPARATIF
A2: Extraction : 02/06/2026 | Résultats calculés automatiquement depuis Data Source
A4: 📊 SYNTHÈSE COMPARÉE
A5: INDICATEUR | B5: PORTEUR | C5: NON PORTEUR | D5: TOTAL | E5: % PORTEURS
A6: Nb Lignes | B6: =COUNTIF('📥 Data Source'!E5:E38201,"Porteur") -> 0 | C6: =COUNTIF('📥 Data Source'!E5:E38201,"Non porteur") -> 0 | D6: =B6+C6 -> 0 | E6: =IFERROR(B6/D6,0) -> 0
A7: Nb Retraits Non Aboutis | B7: =SUMIF('📥 Data Source'!E5:E38201,"Porteur",'📥 Data Source'!F5:F38201) -> 0 | C7: =SUMIF('📥 Data Source'!E5:E38201,"Non porteur",'📥 Data Source'!F5:F38201) -> 0 | D7: =B7+C7 -> 0 | E7: =IFERROR(B7/D7,0) -> 0
A8: Montant Total (€) | B8: =SUMIF('📥 Data Source'!E5:E38201,"Porteur",'📥 Data Source'!G5:G38201) -> 0 | C8: =SUMIF('📥 Data Source'!E5:E38201,"Non porteur",'📥 Data Source'!G5:G38201) -> 0 | D8: =B8+C8 -> 0 | E8: =IFERROR(B8/D8,0) -> 0
A9: Montant Moyen / Retrait (€) | B9: =IFERROR(B8/B7,0) -> 0 | C9: =IFERROR(C8/C7,0) -> 0 | D9: =IFERROR(D8/D7,0) -> 0

Sheet 📈 Graphiques
A1: 📈 TABLEAUX DE BORD — RETRAITS NON SERVIS 2025 | R1: AUTOMATE | S1: NB_RETRAITS | U1: TYPE | V1: NB_RETRAITS | X1: DATE | Y1: MONTANT
A2: Graphiques mis à jour automatiquement depuis Data Source | 02/06/2026 | R2: ='📊 Par Automate'!A10 -> 0 | S2: ='📊 Par Automate'!C10 -> 0 | U2: Porteur | V2: ='👥 Porteur vs Non Porteur'!B7 -> 0 | X2: {=IFERROR(INDEX('📥 Data Source'!$A$5:$A$38201,MATCH(0,COUNTIF($X$1:X1,'📥 Data Source'!$A$5:$A$38201)+IF('📥 Data Source'!$A$5:$A$38201="",1,0),0)),"")} -> 0 | Y2: =IF(X2="","",SUMIF('📥 Data Source'!$A$5:$A$38201,X2,'📥 Data Source'!$G$5:$G$38201)) -> 0
R3: ='📊 Par Automate'!A11 -> 0 | S3: ='📊 Par Automate'!C11 -> 0 | U3: Non porteur | V3: ='👥 Porteur vs Non Porteur'!C7 -> 0 | X3: {=IFERROR(INDEX('📥 Data Source'!$A$5:$A$38201,MATCH(0,COUNTIF($X$1:X2,'📥 Data Source'!$A$5:$A$38201)+IF('📥 Data Source'!$A$5:$A$38201="",1,0),0)),"")} -> 0 | Y3: =IF(X3="","",SUMIF('📥 Data Source'!$A$5:$A$38201,X3,'📥 Data Source'!$G$5:$G$38201)) -> 0
A4: 📊 NB RETRAITS NON ABOUTIS PAR AUTOMATE | I4: 🥧 PORTEUR vs NON PORTEUR | R4: ='📊 Par Automate'!A12 -> 0 | S4: ='📊 Par Automate'!C12 -> 0 | X4: {=IFERROR(INDEX('📥 Data Source'!$A$5:$A$38201,MATCH(0,COUNTIF($X$1:X3,'📥 Data Source'!$A$5:$A$38201)+IF('📥 Data Source'!$A$5:$A$38201="",1,0),0)),"")} -> 0 | Y4: =IF(X4="","",SUMIF('📥 Data Source'!$A$5:$A$38201,X4,'📥 Data Source'!$G$5:$G$38201)) -> 0
R5: ='📊 Par Automate'!A13 -> 0 | S5: ='📊 Par Automate'!C13 -> 0 | X5: {=IFERROR(INDEX('📥 Data Source'!$A$5:$A$38201,MATCH(0,COUNTIF($X$1:X4,'📥 Data Source'!$A$5:$A$38201)+IF('📥 Data Source'!$A$5:$A$38201="",1,0),0)),"")} -> 0 | Y5: =IF(X5="","",SUMIF('📥 Data Source'!$A$5:$A$38201,X5,'📥 Data Source'!$G$5:$G$38201)) -> 0
R6: ='📊 Par Automate'!A14 -> 0 | S6: ='📊 Par Automate'!C14 -> 0 | X6: {=IFERROR(INDEX('📥 Data Source'!$A$5:$A$38201,MATCH(0,COUNTIF($X$1:X5,'📥 Data Source'!$A$5:$A$38201)+IF('📥 Data Source'!$A$5:$A$38201="",1,0),0)),"")} -> 0 | Y6: =IF(X6="","",SUMIF('📥 Data Source'!$A$5:$A$38201,X6,'📥 Data Source'!$G$5:$G$38201)) -> 0
R7: ='📊 Par Automate'!A15 -> 0 | S7: ='📊 Par Automate'!C15 -> 0 | X7: {=IFERROR(INDEX('📥 Data Source'!$A$5:$A$38201,MATCH(0,COUNTIF($X$1:X6,'📥 Data Source'!$A$5:$A$38201)+IF('📥 Data Source'!$A$5:$A$38201="",1,0),0)),"")} -> 0 | Y7: =IF(X7="","",SUMIF('📥 Data Source'!$A$5:$A$38201,X7,'📥 Data Source'!$G$5:$G$38201)) -> 0
R8: ='📊 Par Automate'!A16 -> 0 | S8: ='📊 Par Automate'!C16 -> 0 | X8: {=IFERROR(INDEX('📥 Data Source'!$A$5:$A$38201,MATCH(0,COUNTIF($X$1:X7,'📥 Data Source'!$A$5:$A$38201)+IF('📥 Data Source'!$A$5:$A$38201="",1,0),0)),"")} -> 0 | Y8: =IF(X8="","",SUMIF('📥 Data Source'!$A$5:$A$38201,X8,'📥 Data Source'!$G$5:$G$38201)) -> 0
R9: ='📊 Par Automate'!A17 -> 0 | S9: ='📊 Par Automate'!C17 -> 0 | X9: {=IFERROR(INDEX('📥 Data Source'!$A$5:$A$38201,MATCH(0,COUNTIF($X$1:X8,'📥 Data Source'!$A$5:$A$38201)+IF('📥 Data Source'!$A$5:$A$38201="",1,0),0)),"")} -> 0 | Y9: =IF(X9="","",SUMIF('📥 Data Source'!$A$5:$A$38201,X9,'📥 Data Source'!$G$5:$G$38201)) -> 0
R10: ='📊 Par Automate'!A18 -> 0 | S10: ='📊 Par Automate'!C18 -> 0 | X10: {=IFERROR(INDEX('📥 Data Source'!$A$5:$A$38201,MATCH(0,COUNTIF($X$1:X9,'📥 Data Source'!$A$5:$A$38201)+IF('📥 Data Source'!$A$5:$A$38201="",1,0),0)),"")} -> 0 | Y10: =IF(X10="","",SUMIF('📥 Data Source'!$A$5:$A$38201,X10,'📥 Data Source'!$G$5:$G$38201)) -> 0
R11: ='📊 Par Automate'!A19 -> 0 | S11: ='📊 Par Automate'!C19 -> 0 | X11: {=IFERROR(INDEX('📥 Data Source'!$A$5:$A$38201,MATCH(0,COUNTIF($X$1:X10,'📥 Data Source'!$A$5:$A$38201)+IF('📥 Data Source'!$A$5:$A$38201="",1,0),0)),"")} -> 0 | Y11: =IF(X11="","",SUMIF('📥 Data Source'!$A$5:$A$38201,X11,'📥 Data Source'!$G$5:$G$38201)) -> 0
R12: ='📊 Par Automate'!A20 -> 0 | S12: ='📊 Par Automate'!C20 -> 0 | X12: {=IFERROR(INDEX('📥 Data Source'!$A$5:$A$38201,MATCH(0,COUNTIF($X$1:X11,'📥 Data Source'!$A$5:$A$38201)+IF('📥 Data Source'!$A$5:$A$38201="",1,0),0)),"")} -> 0 | Y12: =IF(X12="","",SUMIF('📥 Data Source'!$A$5:$A$38201,X12,'📥 Data Source'!$G$5:$G$38201)) -> 0
R13: ='📊 Par Automate'!A21 -> 0 | S13: ='📊 Par Automate'!C21 -> 0 | X13: {=IFERROR(INDEX('📥 Data Source'!$A$5:$A$38201,MATCH(0,COUNTIF($X$1:X12,'📥 Data Source'!$A$5:$A$38201)+IF('📥 Data Source'!$A$5:$A$38201="",1,0),0)),"")} -> 0 | Y13: =IF(X13="","",SUMIF('📥 Data Source'!$A$5:$A$38201,X13,'📥 Data Source'!$G$5:$G$38201)) -> 0
R14: ='📊 Par Automate'!A22 -> 0 | S14: ='📊 Par Automate'!C22 -> 0 | X14: {=IFERROR(INDEX('📥 Data Source'!$A$5:$A$38201,MATCH(0,COUNTIF($X$1:X13,'📥 Data Source'!$A$5:$A$38201)+IF('📥 Data Source'!$A$5:$A$38201="",1,0),0)),"")} -> 0 | Y14: =IF(X14="","",SUMIF('📥 Data Source'!$A$5:$A$38201,X14,'📥 Data Source'!$G$5:$G$38201)) -> 0
R15: ='📊 Par Automate'!A23 -> 0 | S15: ='📊 Par Automate'!C23 -> 0 | X15: {=IFERROR(INDEX('📥 Data Source'!$A$5:$A$38201,MATCH(0,COUNTIF($X$1:X14,'📥 Data Source'!$A$5:$A$38201)+IF('📥 Data Source'!$A$5:$A$38201="",1,0),0)),"")} -> 0 | Y15: =IF(X15="","",SUMIF('📥 Data Source'!$A$5:$A$38201,X15,'📥 Data Source'!$G$5:$G$38201)) -> 0
R16: ='📊 Par Automate'!A24 -> 0 | S16: ='📊 Par Automate'!C24 -> 0 | X16: {=IFERROR(INDEX('📥 Data Source'!$A$5:$A$38201,MATCH(0,COUNTIF($X$1:X15,'📥 Data Source'!$A$5:$A$38201)+IF('📥 Data Source'!$A$5:$A$38201="",1,0),0)),"")} -> 0 | Y16: =IF(X16="","",SUMIF('📥 Data Source'!$A$5:$A$38201,X16,'📥 Data Source'!$G$5:$G$38201)) -> 0
... R22: ='📊 Par Automate'!A30 -> 0 | S22: ='📊 Par Automate'!C30 -> 0 | X22: {=IFERROR(INDEX('📥 Data Source'!$A$5:$A$38201,MATCH(0,COUNTIF($X$1:X21,'📥 Data Source'!$A$5:$A$38201)+IF('📥 Data Source'!$A$5:$A$38201="",1,0),0)),"")} -> 0 | Y22: =IF(X22="","",SUMIF('📥 Data Source'!$A$5:$A$38201,X22,'📥 Data Source'!$G$5:$G$38201)) -> 0
A23: 📈 ÉVOLUTION JOURNALIÈRE DES MONTANTS | R23: ='📊 Par Automate'!A31 -> 0 | S23: ='📊 Par Automate'!C31 -> 0 | X23: {=IFERROR(INDEX('📥 Data Source'!$A$5:$A$38201,MATCH(0,COUNTIF($X$1:X22,'📥 Data Source'!$A$5:$A$38201)+IF('📥 Data Source'!$A$5:$A$38201="",1,0),0)),"")} -> 0 | Y23: =IF(X23="","",SUMIF('📥 Data Source'!$A$5:$A$38201,X23,'📥 Data Source'!$G$5:$G$38201)) -> 0
R24: ='📊 Par Automate'!A32 -> 0 | S24: ='📊 Par Automate'!C32 -> 0 | X24: {=IFERROR(INDEX('📥 Data Source'!$A$5:$A$38201,MATCH(0,COUNTIF($X$1:X23,'📥 Data Source'!$A$5:$A$38201)+IF('📥 Data Source'!$A$5:$A$38201="",1,0),0)),"")} -> 0 | Y24: =IF(X24="","",SUMIF('📥 Data Source'!$A$5:$A$38201,X24,'📥 Data Source'!$G$5:$G$38201)) -> 0
R25: ='📊 Par Automate'!A33 -> 0 | S25: ='📊 Par Automate'!C33 -> 0 | X25: {=IFERROR(INDEX('📥 Data Source'!$A$5:$A$38201,MATCH(0,COUNTIF($X$1:X24,'📥 Data Source'!$A$5:$A$38201)+IF('📥 Data Source'!$A$5:$A$38201="",1,0),0)),"")} -> 0 | Y25: =IF(X25="","",SUMIF('📥 Data Source'!$A$5:$A$38201,X25,'📥 Data Source'!$G$5:$G$38201)) -> 0
R26: ='📊 Par Automate'!A34 -> 0 | S26: ='📊 Par Automate'!C34 -> 0 | X26: {=IFERROR(INDEX('📥 Data Source'!$A$5:$A$38201,MATCH(0,COUNTIF($X$1:X25,'📥 Data Source'!$A$5:$A$38201)+IF('📥 Data Source'!$A$5:$A$38201="",1,0),0)),"")} -> 0 | Y26: =IF(X26="","",SUMIF('📥 Data Source'!$A$5:$A$38201,X26,'📥 Data Source'!$G$5:$G$38201)) -> 0
R27: ='📊 Par Automate'!A35 -> 0 | S27: ='📊 Par Automate'!C35 -> 0 | X27: {=IFERROR(INDEX('📥 Data Source'!$A$5:$A$38201,MATCH(0,COUNTIF($X$1:X26,'📥 Data Source'!$A$5:$A$38201)+IF('📥 Data Source'!$A$5:$A$38201="",1,0),0)),"")} -> 0 | Y27: =IF(X27="","",SUMIF('📥 Data Source'!$A$5:$A$38201,X27,'📥 Data Source'!$G$5:$G$38201)) -> 0
R28: ='📊 Par Automate'!A36 -> 0 | S28: ='📊 Par Automate'!C36 -> 0 | X28: {=IFERROR(INDEX('📥 Data Source'!$A$5:$A$38201,MATCH(0,COUNTIF($X$1:X27,'📥 Data Source'!$A$5:$A$38201)+IF('📥 Data Source'!$A$5:$A$38201="",1,0),0)),"")} -> 0 | Y28: =IF(X28="","",SUMIF('📥 Data Source'!$A$5:$A$38201,X28,'📥 Data Source'!$G$5:$G$38201)) -> 0
R29: ='📊 Par Automate'!A37 -> 0 | S29: ='📊 Par Automate'!C37 -> 0 | X29: {=IFERROR(INDEX('📥 Data Source'!$A$5:$A$38201,MATCH(0,COUNTIF($X$1:X28,'📥 Data Source'!$A$5:$A$38201)+IF('📥 Data Source'!$A$5:$A$38201="",1,0),0)),"")} -> 0 | Y29: =IF(X29="","",SUMIF('📥 Data Source'!$A$5:$A$38201,X29,'📥 Data Source'!$G$5:$G$38201)) -> 0
R30: ='📊 Par Automate'!A38 -> 0 | S30: ='📊 Par Automate'!C38 -> 0 | X30: {=IFERROR(INDEX('📥 Data Source'!$A$5:$A$38201,MATCH(0,COUNTIF($X$1:X29,'📥 Data Source'!$A$5:$A$38201)+IF('📥 Data Source'!$A$5:$A$38201="",1,0),0)),"")} -> 0 | Y30: =IF(X30="","",SUMIF('📥 Data Source'!$A$5:$A$38201,X30,'📥 Data Source'!$G$5:$G$38201)) -> 0
R31: ='📊 Par Automate'!A39 -> 0 | S31: ='📊 Par Automate'!C39 -> 0 | X31: {=IFERROR(INDEX('📥 Data Source'!$A$5:$A$38201,MATCH(0,COUNTIF($X$1:X30,'📥 Data Source'!$A$5:$A$38201)+IF('📥 Data Source'!$A$5:$A$38201="",1,0),0)),"")} -> 0 | Y31: =IF(X31="","",SUMIF('📥 Data Source'!$A$5:$A$38201,X31,'📥 Data Source'!$G$5:$G$38201)) -> 0
R32: ='📊 Par Automate'!A40 -> 0 | S32: ='📊 Par Automate'!C40 -> 0 | X32: {=IFERROR(INDEX('📥 Data Source'!$A$5:$A$38201,MATCH(0,COUNTIF($X$1:X31,'📥 Data Source'!$A$5:$A$38201)+IF('📥 Data Source'!$A$5:$A$38201="",1,0),0)),"")} -> 0 | Y32: =IF(X32="","",SUMIF('📥 Data Source'!$A$5:$A$38201,X32,'📥 Data Source'!$G$5:$G$38201)) -> 0
R33: ='📊 Par Automate'!A41 -> 0 | S33: ='📊 Par Automate'!C41 -> 0 | X33: {=IFERROR(INDEX('📥 Data Source'!$A$5:$A$38201,MATCH(0,COUNTIF($X$1:X32,'📥 Data Source'!$A$5:$A$38201)+IF('📥 Data Source'!$A$5:$A$38201="",1,0),0)),"")} -> 0 | Y33: =IF(X33="","",SUMIF('📥 Data Source'!$A$5:$A$38201,X33,'📥 Data Source'!$G$5:$G$38201)) -> 0
R34: ='📊 Par Automate'!A42 -> 0 | S34: ='📊 Par Automate'!C42 -> 0 | X34: {=IFERROR(INDEX('📥 Data Source'!$A$5:$A$38201,MATCH(0,COUNTIF($X$1:X33,'📥 Data Source'!$A$5:$A$38201)+IF('📥 Data Source'!$A$5:$A$38201="",1,0),0)),"")} -> 0 | Y34: =IF(X34="","",SUMIF('📥 Data Source'!$A$5:$A$38201,X34,'📥 Data Source'!$G$5:$G$38201)) -> 0
R35: ='📊 Par Automate'!A43 -> 0 | S35: ='📊 Par Automate'!C43 -> 0 | X35: {=IFERROR(INDEX('📥 Data Source'!$A$5:$A$38201,MATCH(0,COUNTIF($X$1:X34,'📥 Data Source'!$A$5:$A$38201)+IF('📥 Data Source'!$A$5:$A$38201="",1,0),0)),"")} -> 0 | Y35: =IF(X35="","",SUMIF('📥 Data Source'!$A$5:$A$38201,X35,'📥 Data Source'!$G$5:$G$38201)) -> 0
... R51: ='📊 Par Automate'!A59 -> 0 | S51: ='📊 Par Automate'!C59 -> 0 | X51: {=IFERROR(INDEX('📥 Data Source'!$A$5:$A$38201,MATCH(0,COUNTIF($X$1:X50,'📥 Data Source'!$A$5:$A$38201)+IF('📥 Data Source'!$A$5:$A$38201="",1,0),0)),"")} -> 0 | Y51: =IF(X51="","",SUMIF('📥 Data Source'!$A$5:$A$38201,X51,'📥 Data Source'!$G$5:$G$38201)) -> 0
X52: {=IFERROR(INDEX('📥 Data Source'!$A$5:$A$38201,MATCH(0,COUNTIF($X$1:X51,'📥 Data Source'!$A$5:$A$38201)+IF('📥 Data Source'!$A$5:$A$38201="",1,0),0)),"")} -> 0 | Y52: =IF(X52="","",SUMIF('📥 Data Source'!$A$5:$A$38201,X52,'📥 Data Source'!$G$5:$G$38201)) -> 0
X53: {=IFERROR(INDEX('📥 Data Source'!$A$5:$A$38201,MATCH(0,COUNTIF($X$1:X52,'📥 Data Source'!$A$5:$A$38201)+IF('📥 Data Source'!$A$5:$A$38201="",1,0),0)),"")} -> 0 | Y53: =IF(X53="","",SUMIF('📥 Data Source'!$A$5:$A$38201,X53,'📥 Data Source'!$G$5:$G$38201)) -> 0
X54: {=IFERROR(INDEX('📥 Data Source'!$A$5:$A$38201,MATCH(0,COUNTIF($X$1:X53,'📥 Data Source'!$A$5:$A$38201)+IF('📥 Data Source'!$A$5:$A$38201="",1,0),0)),"")} -> 0 | Y54: =IF(X54="","",SUMIF('📥 Data Source'!$A$5:$A$38201,X54,'📥 Data Source'!$G$5:$G$38201)) -> 0
X55: {=IFERROR(INDEX('📥 Data Source'!$A$5:$A$38201,MATCH(0,COUNTIF($X$1:X54,'📥 Data Source'!$A$5:$A$38201)+IF('📥 Data Source'!$A$5:$A$38201="",1,0),0)),"")} -> 0 | Y55: =IF(X55="","",SUMIF('📥 Data Source'!$A$5:$A$38201,X55,'📥 Data Source'!$G$5:$G$38201)) -> 0
X56: {=IFERROR(INDEX('📥 Data Source'!$A$5:$A$38201,MATCH(0,COUNTIF($X$1:X55,'📥 Data Source'!$A$5:$A$38201)+IF('📥 Data Source'!$A$5:$A$38201="",1,0),0)),"")} -> 0 | Y56: =IF(X56="","",SUMIF('📥 Data Source'!$A$5:$A$38201,X56,'📥 Data Source'!$G$5:$G$38201)) -> 0
X57: {=IFERROR(INDEX('📥 Data Source'!$A$5:$A$38201,MATCH(0,COUNTIF($X$1:X56,'📥 Data Source'!$A$5:$A$38201)+IF('📥 Data Source'!$A$5:$A$38201="",1,0),0)),"")} -> 0 | Y57: =IF(X57="","",SUMIF('📥 Data Source'!$A$5:$A$38201,X57,'📥 Data Source'!$G$5:$G$38201)) -> 0
X58: {=IFERROR(INDEX('📥 Data Source'!$A$5:$A$38201,MATCH(0,COUNTIF($X$1:X57,'📥 Data Source'!$A$5:$A$38201)+IF('📥 Data Source'!$A$5:$A$38201="",1,0),0)),"")} -> 0 | Y58: =IF(X58="","",SUMIF('📥 Data Source'!$A$5:$A$38201,X58,'📥 Data Source'!$G$5:$G$38201)) -> 0
X59: {=IFERROR(INDEX('📥 Data Source'!$A$5:$A$38201,MATCH(0,COUNTIF($X$1:X58,'📥 Data Source'!$A$5:$A$38201)+IF('📥 Data Source'!$A$5:$A$38201="",1,0),0)),"")} -> 0 | Y59: =IF(X59="","",SUMIF('📥 Data Source'!$A$5:$A$38201,X59,'📥 Data Source'!$G$5:$G$38201)) -> 0
X60: {=IFERROR(INDEX('📥 Data Source'!$A$5:$A$38201,MATCH(0,COUNTIF($X$1:X59,'📥 Data Source'!$A$5:$A$38201)+IF('📥 Data Source'!$A$5:$A$38201="",1,0),0)),"")} -> 0 | Y60: =IF(X60="","",SUMIF('📥 Data Source'!$A$5:$A$38201,X60,'📥 Data Source'!$G$5:$G$38201)) -> 0
...
